<?xml version="1.0"?>

<robot name="IG52DB">	
	
	<link name="base_link">
    <inertial>
      <origin
        xyz="0 0 0.184799868005312"
        rpy="0 0 0" />
      <mass
        value="7.21517752108585" />
      <inertia
        ixx="0.0575359303331007"
        ixy="0.000101854892928064"
        ixz="1.4050580272022E-05"
        iyy="0.1156615184442"
        iyz="8.13118408977844E-06"
        izz="0.148245723820908" />
    </inertial>
    <visual>
      <origin
        xyz="0 0 0"
        rpy="0 0 0" />
      <geometry>
     		<mesh 
      		filename="package://bot_description/mesh/base_link.dae" />
      </geometry>
    </visual>
    <collision>
      <origin
        xyz="0 0 0.184799868005312"
        rpy="0 0 0" />
      <geometry>
        <box 
        	size="0.49 0.37 0.18" />
      </geometry>
    </collision>
  </link>
    
		<joint
		  name="wheel1_base_link"
		  type="continuous">
		  <origin
		    xyz="0.1905 0.242266 0.130"
		    rpy="0 0 -1.57079632679" />
		  <parent
		    link="base_link" />
		  <child
		    link="wheel1" />
		  <axis
		    xyz="-1 0 0" />
		</joint>  
		<link
		  name="wheel1">
		  <inertial>
		    <origin
		      xyz="0.00243677970803194 -3.79024847591003E-07 4.21247624393661E-07"
		      rpy="0 0 0" />
		    <mass
		      value="0.67751354463347" />
		    <inertia
		      ixx="0.00701389567182806"
		      ixy="-2.02211773010821E-07"
		      ixz="9.77926367510551E-09"
		      iyy="0.00408444856585223"
		      iyz="7.37676493092014E-09"
		      izz="0.00408509355754381" />
		  </inertial>
		  <visual>
		    <origin
		      xyz="0 0 0"
		      rpy="0 0 0" />
		    <geometry>
		      <mesh
		        filename="package://bot_description/mesh/wheel.dae" />
		    </geometry>
		  </visual>
		  <collision>
		    <origin
		      xyz="0 0 0"
		      rpy="0 1.57079632679 0" />
		    <geometry>
		      <cylinder
		        length="0.007" radius="0.13" />
		    </geometry>
		  </collision>
		  <collision>
		    <origin
		      xyz="0 0 0"
		      rpy="0 1.57079632679 0" />
		    <geometry>
		      <cylinder
		        length="0.08" radius="0.127" />
		    </geometry>
		  </collision>
		</link>
  
</robot>
